<mujoco model="x2_t2.5">
  <compiler angle='radian' eulerseq="XYZ" meshdir="./meshes"
    autolimits="true" />

  <option timestep="0.001" />

  <default>
      <default class="x2">
          <site rgba="1 0 0 1" size="0.01" group="5"/>
          <joint damping="0.0" armature="0.03" frictionloss="0.3"/>
          <default class="visual">
              <geom group="2" type="mesh" contype="0" conaffinity="0" density="0"/>
          </default>
          <default class="collision">
              <geom group="3" type="mesh"/>
              <default class="foot">
                  <geom type="sphere" size="0.005"/>
              </default>
          </default>
      </default>
  </default>

  <asset>
    <mesh name="pelvis" file="pelvis.STL"/>
    <mesh name="imu_in_pelvis_link" file="imu_in_pelvis_link.STL"/>
    <mesh name="left_hip_pitch_link" file="left_hip_pitch_link.STL"/>
    <mesh name="left_hip_roll_link" file="left_hip_roll_link.STL"/>
    <mesh name="left_hip_roll_link1" file="left_hip_roll_link.STL" scale="1 0.9 1"/>
    <mesh name="left_hip_yaw_link" file="left_hip_yaw_link.STL"/>
    <mesh name="left_knee_link" file="left_knee_link.STL"/>
    <mesh name="left_ankle_pitch_link" file="left_ankle_pitch_link.STL"/>
    <mesh name="left_ankle_roll_link" file="left_ankle_roll_link.STL"/>
    <mesh name="right_hip_pitch_link" file="right_hip_pitch_link.STL"/>
    <mesh name="right_hip_roll_link" file="right_hip_roll_link.STL"/>
    <mesh name="right_hip_roll_link1" file="right_hip_roll_link.STL" scale="1 0.9 1"/>
    <mesh name="right_hip_yaw_link" file="right_hip_yaw_link.STL"/>
    <mesh name="right_knee_link" file="right_knee_link.STL"/>
    <mesh name="right_ankle_pitch_link" file="right_ankle_pitch_link.STL"/>
    <mesh name="right_ankle_roll_link" file="right_ankle_roll_link.STL"/>
    <mesh name="waist_yaw_link" file="waist_yaw_link.STL"/>
    <mesh name="waist_pitch_link" file="waist_pitch_link.STL"/>
    <mesh name="torso_link" file="torso_link.STL"/>
    <mesh name="imu_in_torso_link" file="imu_in_torso_link.STL"/>
    <mesh name="left_shoulder_pitch_link" file="left_shoulder_pitch_link.STL"/>
    <mesh name="left_shoulder_roll_link" file="left_shoulder_roll_link.STL"/>
    <mesh name="left_shoulder_yaw_link" file="left_shoulder_yaw_link.STL"/>
    <mesh name="left_elbow_link" file="left_elbow_link.STL"/>
    <mesh name="left_wrist_fist_link" file="left_wrist_fist_link.STL"/>
    <mesh name="right_shoulder_pitch_link" file="right_shoulder_pitch_link.STL"/>
    <mesh name="right_shoulder_roll_link" file="right_shoulder_roll_link.STL"/>
    <mesh name="right_shoulder_yaw_link" file="right_shoulder_yaw_link.STL"/>
    <mesh name="right_elbow_link" file="right_elbow_link.STL"/>
    <mesh name="right_wrist_fist_link" file="right_wrist_fist_link.STL"/>
    <mesh name="head_yaw_link" file="head_yaw_link.STL"/>
    <mesh name="head_pitch_link" file="head_pitch_link.STL"/>
    <mesh name="imu_in_head_link" file="imu_in_head_link.STL"/>
    <mesh name="rgbd_head_front_link" file="rgbd_head_front_link.STL"/>
    <mesh name="stereo_head_front_link" file="stereo_head_front_link.STL"/>
    <mesh name="rgb_head_rear_link" file="rgb_head_rear_link.STL"/>
    <mesh name="rgb_head_center_link" file="rgb_head_center_link.STL"/>
  </asset>

  <worldbody>
    <body name="pelvis" pos="0 0 0.68" euler="0 0 0" childclass="x2">
      <light name="tracking" mode="trackcom" pos="0 0 2"/>
      <freejoint name="floating_base_joint"/>
      <geom class="visual" type="mesh" contype="0" conaffinity="0" group="1" density="0" rgba="0.298039 0.298039 0.298039 1" mesh="pelvis"/>
      <geom class="collision" type="mesh" rgba="0.298039 0.298039 0.298039 1" mesh="pelvis"/>
      <geom class="visual" pos="0.0239465 -0.000228682 0.04171" quat="1 0 0 0" type="mesh" contype="0" conaffinity="0" group="1" density="0" mesh="imu_in_pelvis_link"/>
      <site name="imu_0" pos="0.0239465 -0.000228682 0.04171" group="3"/>
      <body name="left_hip_pitch_link" pos="0 0.07135 0">
        <inertial pos="0.007991 0.06415 0.000113" quat="0.515841 0.856422 0.0186858 0.0100156" mass="1.357" diaginertia="0.00215419 0.00150873 0.00148708"/>
        <joint name="left_hip_pitch_joint" pos="0 0 0" axis="0 1 0" range="-2.704 2.556" actuatorfrcrange="-120 120"/>
        <geom class="visual" type="mesh" contype="0" conaffinity="0" group="1" density="0" rgba="0.298039 0.298039 0.298039 1" mesh="left_hip_pitch_link"/>
        <geom class="collision" type="mesh" rgba="0.298039 0.298039 0.298039 1" mesh="left_hip_pitch_link"/>
        <body name="left_hip_roll_link" pos="-0.000575 0.0657 0">
          <inertial pos="3.8e-05 0.000211 -0.094067" quat="0.703753 0.0196362 0.0147649 0.71002" mass="1.52328" diaginertia="0.0040051 0.00361389 0.00238"/>
          <joint name="left_hip_roll_joint" pos="0 0 0" axis="1 0 0" range="-0.235 2.906" actuatorfrcrange="-120 120"/>
          <geom class="visual" type="mesh" contype="0" conaffinity="0" group="1" density="0" rgba="1 1 1 1" mesh="left_hip_roll_link"/>
          <geom class="collision" type="mesh" rgba="1 1 1 1" mesh="left_hip_roll_link1"/>
          <body name="left_hip_yaw_link" pos="0.000575 0 -0.13685">
            <inertial pos="-0.002516 0.003987 -0.145193" quat="0.693451 0.0207364 0.0466441 0.718693" mass="1.92706" diaginertia="0.0102154 0.00962136 0.00220922"/>
            <joint name="left_hip_yaw_joint" pos="0 0 0" axis="0 0 1" range="-1.684 3.43" actuatorfrcrange="-120 120"/>
            <geom class="visual" type="mesh" contype="0" conaffinity="0" group="1" density="0" rgba="1 1 1 1" mesh="left_hip_yaw_link"/>
            <geom class="collision" type="mesh" rgba="1 1 1 1" mesh="left_hip_yaw_link"/>
            <body name="left_knee_link" pos="-0.00766 0.000225 -0.1831">
              <inertial pos="-0.004377 0.004596 -0.120164" quat="0.544625 0.0410593 0.00185755 0.837672" mass="2.02931" diaginertia="0.00751825 0.00736199 0.00209376"/>
              <joint name="left_knee_joint" pos="0 0 0" axis="0 1 0" range="0 2.4073" actuatorfrcrange="-120 120"/>
              <geom class="visual" type="mesh" contype="0" conaffinity="0" group="1" density="0" rgba="1 1 1 1" mesh="left_knee_link"/>
              <geom class="collision" type="mesh" rgba="1 1 1 1" mesh="left_knee_link"/>
              <body name="left_ankle_pitch_link" pos="-0.01 -0.000124911 -0.282">
                <inertial pos="0.011533 -0.000196 0.003633" quat="0.771201 -0.0277372 0.0916759 0.629345" mass="0.733802" diaginertia="0.00105931 0.000971011 0.000597681"/>
                <joint name="left_ankle_pitch_joint" pos="0 0 0" axis="0 1 0" range="-0.803 0.453" actuatorfrcrange="-36 36"/>
                <geom class="visual" type="mesh" contype="0" conaffinity="0" group="1" density="0" rgba="0.298039 0.298039 0.298039 1" mesh="left_ankle_pitch_link"/>
                <!-- <geom type="mesh" rgba="0.298039 0.298039 0.298039 1" mesh="left_ankle_pitch_link"/> -->
                <body name="left_ankle_roll_link" pos="-0.00175 0 0">
                  <inertial pos="0.035428 2.5e-05 -0.049572" quat="8.87731e-05 0.697702 -0.000148831 0.716388" mass="1.01617" diaginertia="0.0044933 0.004165 0.0011997"/>
                  <joint name="left_ankle_roll_joint" pos="0 0 0" axis="1 0 0" range="-0.262 0.262" actuatorfrcrange="-24 24"/>
                  <geom class="visual" type="mesh" contype="0" conaffinity="0" group="1" density="0" rgba="1 0.5 0 1" mesh="left_ankle_roll_link"/>
                  <!-- <geom type="mesh" rgba="1 0.5 0 1" mesh="left_ankle_roll_link"/> -->
                  <geom class="collision" type="sphere" size="0.005" pos="-0.05 0.05 -0.068" rgba="1 0.5 0 1"/>
                  <geom class="collision" type="sphere" size="0.005" pos="-0.065 0.025 -0.068" rgba="1 0.5 0 1"/>
                  <geom class="collision" type="sphere" size="0.005" pos="-0.05 -0.05 -0.068" rgba="1 0.5 0 1"/>
                  <geom class="collision" type="sphere" size="0.005" pos="-0.065 -0.025 -0.068" rgba="1 0.5 0 1"/>
                  <geom class="collision" type="sphere" size="0.005" pos="0.11 0.05 -0.068" rgba="1 0.5 0 1"/>
                  <geom class="collision" type="sphere" size="0.005" pos="0.11 -0.05 -0.068" rgba="1 0.5 0 1"/>
                  <geom class="collision" type="sphere" size="0.005" pos="-0.02 -0.06 -0.068" rgba="1 0.5 0 1"/>
                  <geom class="collision" type="sphere" size="0.005" pos="-0.02 0.06 -0.068" rgba="1 0.5 0 1"/>
                  <geom class="collision" type="sphere" size="0.005" pos="0.07 -0.06 -0.068" rgba="1 0.5 0 1"/>
                  <geom class="collision" type="sphere" size="0.005" pos="0.07 0.06 -0.068" rgba="1 0.5 0 1"/>
                  <geom class="collision" type="sphere" size="0.005" pos="0.139 0 -0.066" rgba="1 0.5 0 1"/>
                  <geom class="collision" type="sphere" size="0.005" pos="0.128 0 -0.02" rgba="1 0.5 0 1"/>
                </body>
              </body>
            </body>
          </body>
        </body>
      </body>
      <body name="right_hip_pitch_link" pos="0 -0.07135 0">
        <inertial pos="0.007991 -0.064127 0.000129" quat="0.858045 0.513139 -0.00989931 -0.0186798" mass="1.35791" diaginertia="0.00215719 0.00151134 0.00148747"/>
        <joint name="right_hip_pitch_joint" pos="0 0 0" axis="0 1 0" range="-2.704 2.556" actuatorfrcrange="-120 120"/>
        <geom class="visual" type="mesh" contype="0" conaffinity="0" group="1" density="0" rgba="0.298039 0.298039 0.298039 1" mesh="right_hip_pitch_link"/>
        <geom class="collision" type="mesh" rgba="0.298039 0.298039 0.298039 1" mesh="right_hip_pitch_link"/>
        <body name="right_hip_roll_link" pos="0 -0.0657 0">
          <inertial pos="-0.000598 -0.000208 -0.094133" quat="0.711029 0.0161232 0.0210552 0.702662" mass="1.52356" diaginertia="0.00399713 0.00361637 0.0023795"/>
          <joint name="right_hip_roll_joint" pos="0 0 0" axis="1 0 0" range="-2.906 0.235" actuatorfrcrange="-120 120"/>
          <geom class="visual" type="mesh" contype="0" conaffinity="0" group="1" density="0" rgba="1 1 1 1" mesh="right_hip_roll_link"/>
          <geom class="collision" type="mesh" rgba="1 1 1 1" mesh="right_hip_roll_link1"/>
          <body name="right_hip_yaw_link" pos="0 0 -0.13685">
            <inertial pos="-0.002588 -0.004008 -0.145259" quat="0.749414 -0.0168454 -0.0474655 0.660184" mass="1.91913" diaginertia="0.0102112 0.00960116 0.00220367"/>
            <joint name="right_hip_yaw_joint" pos="0 0 0" axis="0 0 1" range="-3.43 1.684" actuatorfrcrange="-120 120"/>
            <geom class="visual" type="mesh" contype="0" conaffinity="0" group="1" density="0" rgba="1 1 1 1" mesh="right_hip_yaw_link"/>
            <geom class="collision" type="mesh" rgba="1 1 1 1" mesh="right_hip_yaw_link"/>
            <body name="right_knee_link" pos="-0.00766 -0.000225 -0.1831">
              <inertial pos="-0.004421 -0.004597 -0.119691" quat="0.843208 0.00193882 0.0393296 0.536144" mass="2.03086" diaginertia="0.00756687 0.0074197 0.00209643"/>
              <joint name="right_knee_joint" pos="0 0 0" axis="0 1 0" range="0 2.4073" actuatorfrcrange="-120 120"/>
              <geom class="visual" type="mesh" contype="0" conaffinity="0" group="1" density="0" rgba="1 1 1 1" mesh="right_knee_link"/>
              <geom class="collision" type="mesh" rgba="1 1 1 1" mesh="right_knee_link"/>
              <body name="right_ankle_pitch_link" pos="-0.01 0.000124911 -0.282">
                <inertial pos="0.011506 0.000943 0.004032" quat="0.679083 0.084235 -0.0122228 0.72911" mass="0.735566" diaginertia="0.00110225 0.00102346 0.000600294"/>
                <joint name="right_ankle_pitch_joint" pos="0 0 0" axis="0 1 0" range="-0.803 0.453" actuatorfrcrange="-36 36"/>
                <geom class="visual" type="mesh" contype="0" conaffinity="0" group="1" density="0" rgba="0.298039 0.298039 0.298039 1" mesh="right_ankle_pitch_link"/>
                <!-- <geom class="collision" type="mesh" rgba="0.298039 0.298039 0.298039 1" mesh="right_ankle_pitch_link"/> -->
                <body name="right_ankle_roll_link" pos="-0.00175 0 0">
                  <inertial pos="0.035428 2.5e-05 -0.049572" quat="8.87731e-05 0.697702 -0.000148831 0.716388" mass="1.01617" diaginertia="0.0044933 0.004165 0.0011997"/>
                  <joint name="right_ankle_roll_joint" pos="0 0 0" axis="1 0 0" range="-0.2625 0.2625" actuatorfrcrange="-24 24"/>
                  <geom class="visual" type="mesh" contype="0" conaffinity="0" group="1" density="0" rgba="1 0.5 0 1" mesh="right_ankle_roll_link"/>
                  <geom class="collision" type="sphere" size="0.005" pos="-0.05 0.05 -0.068" rgba="1 0.5 0 1"/>
                  <geom class="collision" type="sphere" size="0.005" pos="-0.065 0.025 -0.068" rgba="1 0.5 0 1"/>
                  <geom class="collision" type="sphere" size="0.005" pos="-0.05 -0.05 -0.068" rgba="1 0.5 0 1"/>
                  <geom class="collision" type="sphere" size="0.005" pos="-0.065 -0.025 -0.068" rgba="1 0.5 0 1"/>
                  <geom class="collision" type="sphere" size="0.005" pos="0.11 0.05 -0.068" rgba="1 0.5 0 1"/>
                  <geom class="collision" type="sphere" size="0.005" pos="0.11 -0.05 -0.068" rgba="1 0.5 0 1"/>
                  <geom class="collision" type="sphere" size="0.005" pos="-0.02 -0.06 -0.068" rgba="1 0.5 0 1"/>
                  <geom class="collision" type="sphere" size="0.005" pos="-0.02 0.06 -0.068" rgba="1 0.5 0 1"/>
                  <geom class="collision" type="sphere" size="0.005" pos="0.07 -0.06 -0.068" rgba="1 0.5 0 1"/>
                  <geom class="collision" type="sphere" size="0.005" pos="0.07 0.06 -0.068" rgba="1 0.5 0 1"/>
                  <geom class="collision" type="sphere" size="0.005" pos="0.139 0 -0.066" rgba="1 0.5 0 1"/>
                  <geom class="collision" type="sphere" size="0.005" pos="0.128 0 -0.02" rgba="1 0.5 0 1"/>
                </body>
              </body>
            </body>
          </body>
        </body>
      </body>
      <body name="waist_yaw_link" pos="0 0 0.06706">
        <inertial pos="-0.001416 4.7e-05 0.0419" quat="0.510453 0.50273 -0.496552 0.490037" mass="1.62054" diaginertia="0.00209976 0.00150108 0.00121861"/>
        <joint name="waist_yaw_joint" pos="0 0 0" axis="0 0 1" range="-3.43 2.382" actuatorfrcrange="-120 120"/>
        <geom class="visual" type="mesh" contype="0" conaffinity="0" group="1" density="0" rgba="0.298039 0.298039 0.298039 1" mesh="waist_yaw_link"/>
        <body name="waist_pitch_link" pos="0 0 0.0880106">
          <inertial pos="0.008967 -1e-06 0" quat="0.5 0.5 -0.5 0.5" mass="0.392413" diaginertia="0.000198 0.000133 0.000102"/>
          <joint name="waist_pitch_joint" pos="0 0 0" axis="0 1 0" range="-0.314 0.314" actuatorfrcrange="-48 48"/>
          <geom class="visual" type="mesh" contype="0" conaffinity="0" group="1" density="0" rgba="0.298039 0.298039 0.298039 1" mesh="waist_pitch_link"/>
          <body name="torso_link">
            <inertial pos="-0.001057 -0.000191 0.196815" quat="0.996641 -0.00061382 0.0818265 -0.00327102" mass="8.48344" diaginertia="0.0958584 0.0744011 0.0579505"/>
            <joint name="waist_roll_joint" pos="0 0 0" axis="1 0 0" range="-0.488 0.488" actuatorfrcrange="-48 48"/>
            <geom class="visual" type="mesh" contype="0" conaffinity="0" group="1" density="0" rgba="1 1 1 1" mesh="torso_link"/>
            <geom class="collision" type="mesh" rgba="1 1 1 1" mesh="torso_link"/>
            <geom class="visual" pos="-0.0248787 0.00198528 0.105938" quat="1 0 0 0" type="mesh" contype="0" conaffinity="0" group="1" density="0" rgba="0.647059 0.619608 0.588235 1" mesh="imu_in_torso_link"/>
            <site name="imu_2" pos="-0.0248787 0.00198528 0.105938" group="3"/>
            <body name="left_shoulder_pitch_link" pos="0.00329907 0.143032 0.241648" quat="0.994522 0.104528 0 0">
              <inertial pos="0.003145 0.050137 5.8e-05" quat="0.692767 0.721028 0.0137298 -0.00183176" mass="0.831236" diaginertia="0.000742078 0.000648995 0.000624927"/>
              <joint name="left_shoulder_pitch_joint" pos="0 0 0" axis="0 1 0" range="-3.08 2.04" actuatorfrcrange="-36 36"/>
              <geom class="visual" type="mesh" contype="0" conaffinity="0" group="1" density="0" rgba="0.298039 0.298039 0.298039 1" mesh="left_shoulder_pitch_link"/>
              <geom class="collision" type="mesh" rgba="0.298039 0.298039 0.298039 1" mesh="left_shoulder_pitch_link"/>
              <body name="left_shoulder_roll_link" pos="-0.000499991 0.0495 0">
                <inertial pos="0.000611 -0.000173 -0.079652" quat="0.705472 0.0288711 0.0233416 0.707765" mass="0.675941" diaginertia="0.00101503 0.000931367 0.000496601"/>
                <joint name="left_shoulder_roll_joint" pos="0 0 0" axis="1 0 0" range="-0.061 2.993" actuatorfrcrange="-36 36"/>
                <geom class="visual" type="mesh" contype="0" conaffinity="0" group="1" density="0" rgba="1 1 1 1" mesh="left_shoulder_roll_link"/>
                <geom class="collision" type="mesh" rgba="1 1 1 1" mesh="left_shoulder_roll_link"/>
                <body name="left_shoulder_yaw_link" pos="0.00122424 0 -0.121195" quat="0.999996 0 -0.00298782 0">
                  <inertial pos="0.010558 0.000194 -0.071776" quat="0.991118 -0.00200113 0.131015 -0.0227091" mass="0.654863" diaginertia="0.000784883 0.000757946 0.000402171"/>
                  <joint name="left_shoulder_yaw_joint" pos="0 0 0" axis="0 0 1" range="-2.556 2.556" actuatorfrcrange="-24 24"/>
                  <geom class="visual" type="mesh" contype="0" conaffinity="0" group="1" density="0" rgba="1 1 1 1" mesh="left_shoulder_yaw_link"/>
                  <geom class="collision" type="mesh" rgba="1 1 1 1" mesh="left_shoulder_yaw_link"/>
                  <body name="left_elbow_link" pos="0.014 0.000199986 -0.08295" quat="0.999996 0 0.00298782 0">
                    <inertial pos="-0.013074 0.003849 -0.080631" quat="0.957943 0.148811 -0.0108355 0.245119" mass="0.652072" diaginertia="0.000776506 0.000756912 0.000363582"/>
                    <joint name="left_elbow_joint" pos="0 0 0" axis="0 1 0" range="-2.3556 0" actuatorfrcrange="-24 24"/>
                    <geom class="visual" type="mesh" contype="0" conaffinity="0" group="1" density="0" rgba="1 1 1 1" mesh="left_elbow_link"/>
                    <geom class="collision" type="mesh" rgba="1 1 1 1" mesh="left_elbow_link"/>
                    <body name="left_wrist_yaw_link" pos="-0.01328 -9.7549e-05 -0.12058">
                      <inertial pos="0.0024652 -0.000748 -0.102149" quat="0.601477 0.0186765 0.00664854 0.798644" mass="0.537" diaginertia="0.00288879 0.0028003 0.000437215"/>
                      <joint name="left_wrist_yaw_joint" pos="0 0 0" axis="0 0 -1" range="-2.556 2.556" actuatorfrcrange="-24 24"/>
                      <geom class="visual" type="mesh" contype="0" conaffinity="0" group="1" density="0" rgba="1 1 1 1" mesh="left_wrist_fist_link"/>
                      <geom class="collision" type="mesh" rgba="1 1 1 1" mesh="left_wrist_fist_link"/>
                    </body>
                  </body>
                </body>
              </body>
            </body>
            <body name="right_shoulder_pitch_link" pos="0.00330094 -0.143031 0.241648" quat="0.994522 -0.10453 0 0">
              <inertial pos="0.002751 -0.050128 3.4e-05" quat="0.721271 0.692559 -0.00209904 -0.0112618" mass="0.840966" diaginertia="0.000742051 0.000661027 0.000636922"/>
              <joint name="right_shoulder_pitch_joint" pos="0 0 0" axis="0 1 0" range="-3.08 2.04" actuatorfrcrange="-36 36"/>
              <geom class="visual" type="mesh" contype="0" conaffinity="0" group="1" density="0" rgba="0.298039 0.298039 0.298039 1" mesh="right_shoulder_pitch_link"/>
              <geom class="collision" type="mesh" rgba="0.298039 0.298039 0.298039 1" mesh="right_shoulder_pitch_link"/>
              <body name="right_shoulder_roll_link" pos="-0.0005 -0.0495 0" quat="1 0 7.70015e-05 0">
                <inertial pos="0.000598 0.000175 -0.080798" quat="0.707313 0.00154651 0.00777756 0.706856" mass="0.666354" diaginertia="0.000943035 0.000868066 0.000488899"/>
                <joint name="right_shoulder_roll_joint" pos="0 0 0" axis="1 0 0" range="-2.993 0.061" actuatorfrcrange="-36 36"/>
                <geom class="visual" type="mesh" contype="0" conaffinity="0" group="1" density="0" rgba="1 1 1 1" mesh="right_shoulder_roll_link"/>
                <geom class="collision" type="mesh" rgba="1 1 1 1" mesh="right_shoulder_roll_link"/>
                <body name="right_shoulder_yaw_link" pos="0.0005 0 -0.1212">
                  <inertial pos="0.010616 -0.000193 -0.071783" quat="0.991317 0.00190986 0.12957 0.0223181" mass="0.654829" diaginertia="0.000783316 0.000755947 0.000400737"/>
                  <joint name="right_shoulder_yaw_joint" pos="0 0 0" axis="0 0 1" range="-2.556 2.556" actuatorfrcrange="-24 24"/>
                  <geom class="visual" type="mesh" contype="0" conaffinity="0" group="1" density="0" rgba="1 1 1 1" mesh="right_shoulder_yaw_link"/>
                  <geom class="collision" type="mesh" rgba="1 1 1 1" mesh="right_shoulder_yaw_link"/>
                  <body name="right_elbow_link" pos="0.014 -0.0002 -0.08295">
                    <inertial pos="-0.013435 -0.003857 -0.080674" quat="0.965476 -0.14968 -0.00136848 -0.213192" mass="0.652388" diaginertia="0.000777725 0.000759036 0.000363239"/>
                    <joint name="right_elbow_joint" pos="0 0 0" axis="0 1 0" range="-2.3556 0" actuatorfrcrange="-24 24"/>
                    <geom class="visual" type="mesh" contype="0" conaffinity="0" group="1" density="0" rgba="1 1 1 1" mesh="right_elbow_link"/>
                    <geom class="collision" type="mesh" rgba="1 1 1 1" mesh="right_elbow_link"/>
                    <body name="right_wrist_yaw_link" pos="-0.014 9.75261e-05 -0.120694" quat="1 0 0 1.63671e-05">
                      <inertial pos="0.002044 0.000709 -0.095842" quat="0.797744 0.0034259 0.013954 0.602825" mass="0.569" diaginertia="0.00326351 0.00317372 0.000451784"/>
                      <joint name="right_wrist_yaw_joint" pos="0 0 0" axis="0 0 1" range="-2.556 2.556" actuatorfrcrange="-24 24"/>
                      <geom class="visual" type="mesh" contype="0" conaffinity="0" group="1" density="0" rgba="1 1 1 1" mesh="right_wrist_fist_link"/>
                      <geom class="collision" type="mesh" rgba="1 1 1 1" mesh="right_wrist_fist_link"/>
                    </body>
                  </body>
                </body>
              </body>
            </body>
            <body name="head_yaw_link" pos="0.00834773 0 0.309397">
              <inertial pos="-0.003139 0.001399 0.051838" quat="0.981895 -0.180768 -0.0558932 -0.00900025" mass="0.720047" diaginertia="0.00193595 0.00132396 0.00104809"/>
              <joint name="head_yaw_joint" pos="0 0 0" axis="0 0 1" range="-0.366 0.366" actuatorfrcrange="-2.6 2.6"/>
              <geom class="visual" type="mesh" contype="0" conaffinity="0" group="1" density="0" rgba="0.866667 0.866667 0.890196 1" mesh="head_yaw_link"/>
              <!-- <geom class="collision" type="mesh" rgba="0.866667 0.866667 0.890196 1" mesh="head_yaw_link"/> -->
              <body name="head_pitch_link" pos="0 0 0.0889">
                <inertial pos="0.00524586 -8.20074e-05 0.0061109" quat="0.709677 -0.0852786 -0.0689646 0.695939" mass="1.05439" diaginertia="0.00380138 0.00302231 0.00281748"/>
                <joint name="head_pitch_joint" pos="0 0 0" axis="0 1 0" range="-0.3838 0.3838" actuatorfrcrange="-0.6 0.6"/>
                <geom class="visual" type="mesh" contype="0" conaffinity="0" group="1" density="0" rgba="0.498039 0.498039 0.498039 1" mesh="head_pitch_link"/>
                <geom class="collision" size="0.074 0.05" pos="0 0 0.015" quat="0.499898 0.5 0.5 -0.500102" type="cylinder" rgba="0.498039 0.498039 0.498039 1"/>
                <!-- <geom class="collision" type="mesh" rgba="0.498039 0.498039 0.498039 1" mesh="head_pitch_link"/> -->
                <geom class="visual" pos="0.0259999 -8.25389e-05 0.0176" quat="1 0 0 0" type="mesh" contype="0" conaffinity="0" group="1" density="0" rgba="0.647059 0.619608 0.588235 1" mesh="imu_in_head_link"/>
                <site name="imu_3" pos="0.0259999 -8.25389e-05 0.0176" group="3"/>
                <geom class="visual" pos="0.0576096 -0.0111832 -0.0483697" quat="0.298835 0.640857 0.640857 0.298835" type="mesh" contype="0" conaffinity="0" group="1" density="0" rgba="0.647059 0.619608 0.588235 1" mesh="rgbd_head_front_link"/>
                <geom class="visual" pos="0.067995 0.0297843 0.0499999" quat="0.499205 -0.499205 0.500794 -0.500794" type="mesh" contype="0" conaffinity="0" group="1" density="0" rgba="0.266667 0.266667 0.266667 1" mesh="stereo_head_front_link"/>
                <geom class="visual" pos="-0.0833996 0.000264949 0" quat="0.500794 -0.500794 -0.499205 0.499205" type="mesh" contype="0" conaffinity="0" group="1" density="0" rgba="0.866667 0.866667 0.890196 1" mesh="rgb_head_rear_link"/>
                <geom class="visual" pos="0.0684 -0.000217129 0.05" quat="0.499205 -0.499205 0.500794 -0.500794" type="mesh" contype="0" conaffinity="0" group="1" density="0" rgba="0.501961 0.501961 0.501961 1" mesh="rgb_head_center_link"/>
              </body>
            </body>
          </body>
        </body>
      </body>
    </body>
  </worldbody>
  <actuator>
    <motor class="x2" name="motor_left_hip_pitch_joint" joint="left_hip_pitch_joint" ctrlrange="-118 118"/>
    <motor class="x2" name="motor_left_hip_roll_joint" joint="left_hip_roll_joint" ctrlrange="-118 118"/>
    <motor class="x2" name="motor_left_hip_yaw_joint" joint="left_hip_yaw_joint" ctrlrange="-118 118"/>
    <motor class="x2" name="motor_left_knee_joint" joint="left_knee_joint" ctrlrange="-118 118"/>
    <motor class="x2" name="motor_left_ankle_pitch_joint" joint="left_ankle_pitch_joint" ctrlrange="-36 36"/>
    <motor class="x2" name="motor_left_ankle_roll_joint" joint="left_ankle_roll_joint" ctrlrange="-24 24"/>

    <motor class="x2" name="motor_right_hip_pitch_joint" joint="right_hip_pitch_joint" ctrlrange="-118 118"/>
    <motor class="x2" name="motor_right_hip_roll_joint" joint="right_hip_roll_joint" ctrlrange="-118 118"/>
    <motor class="x2" name="motor_right_hip_yaw_joint" joint="right_hip_yaw_joint" ctrlrange="-118 118"/>
    <motor class="x2" name="motor_right_knee_joint" joint="right_knee_joint" ctrlrange="-118 118"/>
    <motor class="x2" name="motor_right_ankle_pitch_joint" joint="right_ankle_pitch_joint" ctrlrange="-36 36"/>
    <motor class="x2" name="motor_right_ankle_roll_joint" joint="right_ankle_roll_joint" ctrlrange="-24 24"/>

    <motor class="x2" name="motor_waist_yaw_joint" joint="waist_yaw_joint" ctrlrange="-118 118"/>
    <motor class="x2" name="motor_waist_pitch_joint" joint="waist_pitch_joint" ctrlrange="-48 48"/>
    <motor class="x2" name="motor_waist_roll_joint" joint="waist_roll_joint" ctrlrange="-48 48"/>

    <motor class="x2" name="motor_head_yaw_joint" joint="head_yaw_joint" ctrlrange="-2.6 2.6"/>
    <motor class="x2" name="motor_head_pitch_joint" joint="head_pitch_joint" ctrlrange="-0.6 0.6"/>

    <motor class="x2" name="motor_left_shoulder_pitch_joint" joint="left_shoulder_pitch_joint" ctrlrange="-36 36"/>
    <motor class="x2" name="motor_left_shoulder_roll_joint" joint="left_shoulder_roll_joint" ctrlrange="-36 36"/>
    <motor class="x2" name="motor_left_shoulder_yaw_joint" joint="left_shoulder_yaw_joint" ctrlrange="-24 24"/>
    <motor class="x2" name="motor_left_elbow_joint" joint="left_elbow_joint" ctrlrange="-24 24"/>
    <motor class="x2" name="motor_left_wrist_yaw_joint" joint="left_wrist_yaw_joint" ctrlrange="-24 24"/>

    <motor class="x2" name="motor_right_shoulder_pitch_joint" joint="right_shoulder_pitch_joint" ctrlrange="-36 36"/>
    <motor class="x2" name="motor_right_shoulder_roll_joint" joint="right_shoulder_roll_joint" ctrlrange="-36 36"/>
    <motor class="x2" name="motor_right_shoulder_yaw_joint" joint="right_shoulder_yaw_joint" ctrlrange="-24 24"/>
    <motor class="x2" name="motor_right_elbow_joint" joint="right_elbow_joint" ctrlrange="-24 24"/>
    <motor class="x2" name="motor_right_wrist_yaw_joint" joint="right_wrist_yaw_joint" ctrlrange="-24 24"/>
  </actuator>
  <sensor>
    <!-- <gyro name="imu0-gyro" site="imu_0" cutoff="7.85"/>
    <accelerometer name="imu0-acc" site="imu_0" cutoff="157"/>
    <framequat name="imu0-quat" objtype="site" objname="imu_0"/>

    <gyro name="imu1-gyro" site="imu_1" cutoff="7.85"/>
    <accelerometer name="imu1-acc" site="imu_1" cutoff="157"/>
    <framequat name="imu1-quat" objtype="site" objname="imu_1"/> -->

    <framequat name="body-orientation" objtype="site" objname="imu_0" noise="0"/>
    <gyro name="body-angular-velocity" site="imu_0" noise="0.001"/>
    <framepos name="body-linear-pos" objtype="site" objname="imu_0"/>
    <velocimeter name="body-linear-vel" site="imu_0"/>
    <accelerometer name="body-linear-acceleration" site="imu_0" noise="0.001"/>

    <jointpos name = 'jointpos_left_hip_pitch_joint' joint = 'left_hip_pitch_joint' noise = "0" />
    <jointpos name = 'jointpos_left_hip_roll_joint' joint = 'left_hip_roll_joint' noise = "0" />
    <jointpos name = 'jointpos_left_hip_yaw_joint' joint = 'left_hip_yaw_joint' noise = "0" />
    <jointpos name = 'jointpos_left_knee_joint' joint = 'left_knee_joint' noise = "0" />
    <jointpos name = 'jointpos_left_ankle_pitch_joint' joint = 'left_ankle_pitch_joint' noise = "0" />
    <jointpos name = 'jointpos_left_ankle_roll_joint' joint = 'left_ankle_roll_joint' noise = "0" />

    <jointpos name = 'jointpos_right_hip_pitch_joint' joint = 'right_hip_pitch_joint' noise = "0" />
    <jointpos name = 'jointpos_right_hip_roll_joint' joint = 'right_hip_roll_joint' noise = "0" />
    <jointpos name = 'jointpos_right_hip_yaw_joint' joint = 'right_hip_yaw_joint' noise = "0" />
    <jointpos name = 'jointpos_right_knee_joint' joint = 'right_knee_joint' noise = "0" />
    <jointpos name = 'jointpos_right_ankle_pitch_joint' joint = 'right_ankle_pitch_joint' noise = "0" />
    <jointpos name = 'jointpos_right_ankle_roll_joint' joint = 'right_ankle_roll_joint' noise = "0" />

    <jointpos name = 'jointpos_waist_yaw_joint' joint = 'waist_yaw_joint' noise = "0" />
    <jointpos name = 'jointpos_waist_pitch_joint' joint = 'waist_pitch_joint' noise = "0" />
    <jointpos name = 'jointpos_waist_roll_joint' joint = 'waist_roll_joint' noise = "0" />

    <jointpos name = 'jointpos_head_yaw_joint' joint = 'head_yaw_joint' noise = "0" />
    <jointpos name = 'jointpos_head_pitch_joint' joint = 'head_pitch_joint' noise = "0" />

    <jointpos name = 'jointpos_left_shoulder_pitch_joint' joint = 'left_shoulder_pitch_joint' noise = "0" />
    <jointpos name = 'jointpos_left_shoulder_roll_joint' joint = 'left_shoulder_roll_joint' noise = "0" />
    <jointpos name = 'jointpos_left_shoulder_yaw_joint' joint = 'left_shoulder_yaw_joint' noise = "0" />
    <jointpos name = 'jointpos_left_elbow_joint' joint = 'left_elbow_joint' noise = "0" />
    <jointpos name = 'jointpos_left_wrist_yaw_joint' joint = 'left_wrist_yaw_joint' noise = "0" />

    <jointpos name = 'jointpos_right_shoulder_pitch_joint' joint = 'right_shoulder_pitch_joint' noise = "0" />
    <jointpos name = 'jointpos_right_shoulder_roll_joint' joint = 'right_shoulder_roll_joint' noise = "0" />
    <jointpos name = 'jointpos_right_shoulder_yaw_joint' joint = 'right_shoulder_yaw_joint' noise = "0" />
    <jointpos name = 'jointpos_right_elbow_joint' joint = 'right_elbow_joint' noise = "0" />
    <jointpos name = 'jointpos_right_wrist_yaw_joint' joint = 'right_wrist_yaw_joint' noise = "0" />

    <jointvel name = 'jointvel_left_hip_pitch_joint' joint = 'left_hip_pitch_joint' noise = "0" />
    <jointvel name = 'jointvel_left_hip_roll_joint' joint = 'left_hip_roll_joint' noise = "0" />
    <jointvel name = 'jointvel_left_hip_yaw_joint' joint = 'left_hip_yaw_joint' noise = "0" />
    <jointvel name = 'jointvel_left_knee_joint' joint = 'left_knee_joint' noise = "0" />
    <jointvel name = 'jointvel_left_ankle_pitch_joint' joint = 'left_ankle_pitch_joint' noise = "0" />
    <jointvel name = 'jointvel_left_ankle_roll_joint' joint = 'left_ankle_roll_joint' noise = "0" />

    <jointvel name = 'jointvel_right_hip_pitch_joint' joint = 'right_hip_pitch_joint' noise = "0" />
    <jointvel name = 'jointvel_right_hip_roll_joint' joint = 'right_hip_roll_joint' noise = "0" />
    <jointvel name = 'jointvel_right_hip_yaw_joint' joint = 'right_hip_yaw_joint' noise = "0" />
    <jointvel name = 'jointvel_right_knee_joint' joint = 'right_knee_joint' noise = "0" />
    <jointvel name = 'jointvel_right_ankle_pitch_joint' joint = 'right_ankle_pitch_joint' noise = "0" />
    <jointvel name = 'jointvel_right_ankle_roll_joint' joint = 'right_ankle_roll_joint' noise = "0" />

    <jointvel name = 'jointvel_waist_yaw_joint' joint = 'waist_yaw_joint' noise = "0" />
    <jointvel name = 'jointvel_waist_pitch_joint' joint = 'waist_pitch_joint' noise = "0" />
    <jointvel name = 'jointvel_waist_roll_joint' joint = 'waist_roll_joint' noise = "0" />

    <jointvel name = 'jointvel_head_yaw_joint' joint = 'head_yaw_joint' noise = "0" />
    <jointvel name = 'jointvel_head_pitch_joint' joint = 'head_pitch_joint' noise = "0" />

    <jointvel name = 'jointvel_left_shoulder_pitch_joint' joint = 'left_shoulder_pitch_joint' noise = "0" />
    <jointvel name = 'jointvel_left_shoulder_roll_joint' joint = 'left_shoulder_roll_joint' noise = "0" />
    <jointvel name = 'jointvel_left_shoulder_yaw_joint' joint = 'left_shoulder_yaw_joint' noise = "0" />
    <jointvel name = 'jointvel_left_elbow_joint' joint = 'left_elbow_joint' noise = "0" />
    <jointvel name = 'jointvel_left_wrist_yaw_joint' joint = 'left_wrist_yaw_joint' noise = "0" />

    <jointvel name = 'jointvel_right_shoulder_pitch_joint' joint = 'right_shoulder_pitch_joint' noise = "0" />
    <jointvel name = 'jointvel_right_shoulder_roll_joint' joint = 'right_shoulder_roll_joint' noise = "0" />
    <jointvel name = 'jointvel_right_shoulder_yaw_joint' joint = 'right_shoulder_yaw_joint' noise = "0" />
    <jointvel name = 'jointvel_right_elbow_joint' joint = 'right_elbow_joint' noise = "0" />
    <jointvel name = 'jointvel_right_wrist_yaw_joint' joint = 'right_wrist_yaw_joint' noise = "0" />

  </sensor>
</mujoco>
